Workbook
Name Slicer_Category: #N/A
Name Slicer_Month: #N/A
Name Slicer_Payment_Mode: #N/A
Name Slicer_Region: #N/A
Name Slicer_Salesperson: #N/A
Name Slicer_State: #N/A

Sheet Raw_Data
A1: ELECTRONICS SALES – RAW DATA
A4: Order ID | B4: Order Date | C4: Customer Name | D4: City | E4: State | F4: Region | G4: Category | H4: Product Name | I4: Quantity | J4: Unit Price | K4: Discount % | L4: Sales Amount | M4: Profit | N4: Payment Mode | O4: Salesperson
A5: ORD-1001 | B5: 45691 | C5: Karan Joshi | D5: Coimbatore | E5: Tamil Nadu | F5: South | G5: Accessories | H5: Keyboard | I5: 2 | J5: 1500 | K5: 0 | L5: 3000 | M5: =RawSalesTable[[#This Row],[Sales Amount]]-RawSalesTable[[#This Row],[Quantity]]*RawSalesTable[[#This Row],[Unit Price]] -> 0 | N5: Net Banking | O5: Meera
A6: ORD-1002 | B6: 45909 | C6: Neha Patil | D6: Dwarka | E6: Delhi | F6: North | G6: Audio | H6: Bluetooth Speaker | I6: 2 | J6: 3200 | K6: 0 | L6: 6400 | M6: =RawSalesTable[[#This Row],[Sales Amount]]-RawSalesTable[[#This Row],[Quantity]]*RawSalesTable[[#This Row],[Unit Price]] -> 0 | N6: Net Banking | O6: Diya
A7: ORD-1003 | B7: 45837 | C7: Amit Shah | D7: Udaipur | E7: Rajasthan | F7: North | G7: Audio | H7: Headphones | I7: 1 | J7: 2800 | K7: 0.1 | L7: 2520 | M7: =RawSalesTable[[#This Row],[Sales Amount]]-RawSalesTable[[#This Row],[Quantity]]*RawSalesTable[[#This Row],[Unit Price]] -> -280 | N7: Cash | O7: Vivaan
A8: ORD-1004 | B8: 45730 | C8: Neha Patil | D8: Vadodara | E8: Gujarat | F8: West | G8: Accessories | H8: USB Hub | I8: 2 | J8: 1200 | K8: 0.15 | L8: 2040 | M8: =RawSalesTable[[#This Row],[Sales Amount]]-RawSalesTable[[#This Row],[Quantity]]*RawSalesTable[[#This Row],[Unit Price]] -> -360 | N8: Cash | O8: Vivaan
A9: ORD-1005 | B9: 46020 | C9: Raj Mehta | D9: Chennai | E9: Tamil Nadu | F9: South | G9: Monitor | H9: LG 24 inch | I9: 2 | J9: 13500 | K9: 0.1 | L9: 24300 | M9: =RawSalesTable[[#This Row],[Sales Amount]]-RawSalesTable[[#This Row],[Quantity]]*RawSalesTable[[#This Row],[Unit Price]] -> -2700 | N9: Debit Card | O9: Aarav
A10: ORD-1006 | B10: 45951 | C10: Anaya Singh | D10: Vadodara | E10: Gujarat | F10: West | G10: Laptop | H10: Lenovo IdeaPad | I10: 2 | J10: 58000 | K10: 0.05 | L10: 110200 | M10: =RawSalesTable[[#This Row],[Sales Amount]]-RawSalesTable[[#This Row],[Quantity]]*RawSalesTable[[#This Row],[Unit Price]] -> -5800 | N10: Cash | O10: Diya
A11: ORD-1007 | B11: 45738 | C11: Karan Joshi | D11: Dwarka | E11: Delhi | F11: North | G11: Audio | H11: Wireless Earbuds | I11: 1 | J11: 4500 | K11: 0.05 | L11: 4275 | M11: =RawSalesTable[[#This Row],[Sales Amount]]-RawSalesTable[[#This Row],[Quantity]]*RawSalesTable[[#This Row],[Unit Price]] -> -225 | N11: Credit Card | O11: Isha
A12: ORD-1008 | B12: 45764 | C12: Riya Kapoor | D12: Rohini | E12: Delhi | F12: North | G12: Laptop | H12: HP 15s | I12: 2 | J12: 61000 | K12: 0 | L12: 122000 | M12: =RawSalesTable[[#This Row],[Sales Amount]]-RawSalesTable[[#This Row],[Quantity]]*RawSalesTable[[#This Row],[Unit Price]] -> 0 | N12: Net Banking | O12: Diya
A13: ORD-1009 | B13: 45812 | C13: Karan Joshi | D13: Dwarka | E13: Delhi | F13: North | G13: Laptop | H13: Lenovo IdeaPad | I13: 3 | J13: 58000 | K13: 0 | L13: 174000 | M13: =RawSalesTable[[#This Row],[Sales Amount]]-RawSalesTable[[#This Row],[Quantity]]*RawSalesTable[[#This Row],[Unit Price]] -> 0 | N13: Net Banking | O13: Diya
A14: ORD-1010 | B14: 45669 | C14: Karan Joshi | D14: Dwarka | E14: Delhi | F14: North | G14: Audio | H14: Wireless Earbuds | I14: 1 | J14: 4500 | K14: 0.15 | L14: 3825 | M14: =RawSalesTable[[#This Row],[Sales Amount]]-RawSalesTable[[#This Row],[Quantity]]*RawSalesTable[[#This Row],[Unit Price]] -> -675 | N14: Credit Card | O14: Isha
A15: ORD-1011 | B15: 45755 | C15: Karan Joshi | D15: Jodhpur | E15: Rajasthan | F15: North | G15: Laptop | H15: Acer Aspire 5 | I15: 1 | J15: 52000 | K15: 0.05 | L15: 49400 | M15: =RawSalesTable[[#This Row],[Sales Amount]]-RawSalesTable[[#This Row],[Quantity]]*RawSalesTable[[#This Row],[Unit Price]] -> -2600 | N15: Net Banking | O15: Diya
A16: ORD-1012 | B16: 45750 | C16: Sneha Rao | D16: Nashik | E16: Maharashtra | F16: West | G16: Audio | H16: Wireless Earbuds | I16: 4 | J16: 4500 | K16: 0 | L16: 18000 | M16: =RawSalesTable[[#This Row],[Sales Amount]]-RawSalesTable[[#This Row],[Quantity]]*RawSalesTable[[#This Row],[Unit Price]] -> 0 | N16: UPI | O16: Kavya
... A324: ORD-1320 | B324: 45805 | C324: Neha Patil | D324: Rohini | E324: Delhi | F324: North | G324: Accessories | H324: Keyboard | I324: 2 | J324: 1500 | K324: 0.05 | L324: 2850 | M324: =RawSalesTable[[#This Row],[Sales Amount]]-RawSalesTable[[#This Row],[Quantity]]*RawSalesTable[[#This Row],[Unit Price]] -> -150 | N324: Net Banking | O324: Aditya

Sheet Clean_Data
A1: CLEANED ELECTRONICS SALES DATA
A4: Order ID | B4: Order Date | C4: Customer Name | D4: City | E4: State | F4: Region | G4: Category | H4: Product Name | I4: Quantity | J4: Unit Price | K4: Discount % | L4: Sales Amount | M4: Profit | N4: Payment Mode | O4: Salesperson | P4: Sales Level | Q4: Profit Status | R4: Month
A5: ORD-1001 | B5: 45691 | C5: Karan Joshi | D5: Coimbatore | E5: Tamil Nadu | F5: South | G5: Accessories | H5: Keyboard | I5: 2 | J5: 1500 | K5: 0 | L5: 3000 | M5: =CleanSalesTable[[#This Row],[Sales Amount]]-CleanSalesTable[[#This Row],[Unit Price]] -> 1500 | N5: Net Banking | O5: Meera | P5: =IF(L5>=100000,"High",IF(L5>=30000,"Medium","Low")) -> Low | Q5: =IF(M5>0,"Profit","Loss") -> Profit | R5: =TEXT(B5,"mmm") -> Feb
A6: ORD-1002 | B6: 45909 | C6: Neha Patil | D6: Dwarka | E6: Delhi | F6: North | G6: Audio | H6: Bluetooth Speaker | I6: 2 | J6: 3200 | K6: 0 | L6: 68400 | M6: =CleanSalesTable[[#This Row],[Sales Amount]]-CleanSalesTable[[#This Row],[Unit Price]] -> 65200 | N6: Net Banking | O6: Diya | P6: =IF(L6>=100000,"High",IF(L6>=30000,"Medium","Low")) -> Medium | Q6: =IF(M6>0,"Profit","Loss") -> Profit | R6: =TEXT(B6,"mmm") -> Sep
A7: ORD-1003 | B7: 45837 | C7: Amit Shah | D7: Udaipur | E7: Rajasthan | F7: North | G7: Audio | H7: Headphones | I7: 1 | J7: 2800 | K7: 0.1 | L7: 2520 | M7: =CleanSalesTable[[#This Row],[Sales Amount]]-CleanSalesTable[[#This Row],[Unit Price]] -> -280 | N7: Cash | O7: Vivaan | P7: =IF(L7>=100000,"High",IF(L7>=30000,"Medium","Low")) -> Low | Q7: =IF(M7>0,"Profit","Loss") -> Loss | R7: =TEXT(B7,"mmm") -> Jun
A8: ORD-1004 | B8: 45730 | C8: Neha Patil | D8: Vadodara | E8: Gujarat | F8: West | G8: Accessories | H8: USB Hub | I8: 2 | J8: 1200 | K8: 0.15 | L8: 2040 | M8: =CleanSalesTable[[#This Row],[Sales Amount]]-CleanSalesTable[[#This Row],[Unit Price]] -> 840 | N8: Cash | O8: Vivaan | P8: =IF(L8>=100000,"High",IF(L8>=30000,"Medium","Low")) -> Low | Q8: =IF(M8>0,"Profit","Loss") -> Profit | R8: =TEXT(B8,"mmm") -> Mar
A9: ORD-1005 | B9: 46020 | C9: Raj Mehta | D9: Chennai | E9: Tamil Nadu | F9: South | G9: Monitor | H9: LG 24 inch | I9: 2 | J9: 13500 | K9: 0.1 | L9: 24300 | M9: =CleanSalesTable[[#This Row],[Sales Amount]]-CleanSalesTable[[#This Row],[Unit Price]] -> 10800 | N9: Debit Card | O9: Aarav | P9: =IF(L9>=100000,"High",IF(L9>=30000,"Medium","Low")) -> Low | Q9: =IF(M9>0,"Profit","Loss") -> Profit | R9: =TEXT(B9,"mmm") -> Dec
A10: ORD-1006 | B10: 45951 | C10: Anaya Singh | D10: Vadodara | E10: Gujarat | F10: West | G10: Laptop | H10: Lenovo IdeaPad | I10: 2 | J10: 58000 | K10: 0.05 | L10: 110200 | M10: =CleanSalesTable[[#This Row],[Sales Amount]]-CleanSalesTable[[#This Row],[Unit Price]] -> 52200 | N10: Cash | O10: Diya | P10: =IF(L10>=100000,"High",IF(L10>=30000,"Medium","Low")) -> High | Q10: =IF(M10>0,"Profit","Loss") -> Profit | R10: =TEXT(B10,"mmm") -> Oct
A11: ORD-1007 | B11: 45738 | C11: Karan Joshi | D11: Dwarka | E11: Delhi | F11: North | G11: Audio | H11: Wireless Earbuds | I11: 1 | J11: 4500 | K11: 0.05 | L11: 4275 | M11: =CleanSalesTable[[#This Row],[Sales Amount]]-CleanSalesTable[[#This Row],[Unit Price]] -> -225 | N11: Credit Card | O11: Isha | P11: =IF(L11>=100000,"High",IF(L11>=30000,"Medium","Low")) -> Low | Q11: =IF(M11>0,"Profit","Loss") -> Loss | R11: =TEXT(B11,"mmm") -> Mar
A12: ORD-1008 | B12: 45764 | C12: Riya Kapoor | D12: Rohini | E12: Delhi | F12: North | G12: Laptop | H12: HP 15s | I12: 2 | J12: 61000 | K12: 0 | L12: 122000 | M12: =CleanSalesTable[[#This Row],[Sales Amount]]-CleanSalesTable[[#This Row],[Unit Price]] -> 61000 | N12: Net Banking | O12: Diya | P12: =IF(L12>=100000,"High",IF(L12>=30000,"Medium","Low")) -> High | Q12: =IF(M12>0,"Profit","Loss") -> Profit | R12: =TEXT(B12,"mmm") -> Apr
A13: ORD-1009 | B13: 45812 | C13: Karan Joshi | D13: Dwarka | E13: Delhi | F13: North | G13: Laptop | H13: Lenovo IdeaPad | I13: 3 | J13: 58000 | K13: 0 | L13: 174000 | M13: =CleanSalesTable[[#This Row],[Sales Amount]]-CleanSalesTable[[#This Row],[Unit Price]] -> 116000 | N13: Net Banking | O13: Diya | P13: =IF(L13>=100000,"High",IF(L13>=30000,"Medium","Low")) -> High | Q13: =IF(M13>0,"Profit","Loss") -> Profit | R13: =TEXT(B13,"mmm") -> Jun
A14: ORD-1010 | B14: 45669 | C14: Karan Joshi | D14: Dwarka | E14: Delhi | F14: North | G14: Audio | H14: Wireless Earbuds | I14: 1 | J14: 4500 | K14: 0.15 | L14: 3825 | M14: =CleanSalesTable[[#This Row],[Sales Amount]]-CleanSalesTable[[#This Row],[Unit Price]] -> -675 | N14: Credit Card | O14: Isha | P14: =IF(L14>=100000,"High",IF(L14>=30000,"Medium","Low")) -> Low | Q14: =IF(M14>0,"Profit","Loss") -> Loss | R14: =TEXT(B14,"mmm") -> Jan
A15: ORD-1011 | B15: 45755 | C15: Karan Joshi | D15: Jodhpur | E15: Rajasthan | F15: North | G15: Laptop | H15: Acer Aspire 5 | I15: 1 | J15: 52000 | K15: 0.05 | L15: 49400 | M15: =CleanSalesTable[[#This Row],[Sales Amount]]-CleanSalesTable[[#This Row],[Unit Price]] -> -2600 | N15: Net Banking | O15: Diya | P15: =IF(L15>=100000,"High",IF(L15>=30000,"Medium","Low")) -> Medium | Q15: =IF(M15>0,"Profit","Loss") -> Loss | R15: =TEXT(B15,"mmm") -> Apr
A16: ORD-1012 | B16: 45750 | C16: Sneha Rao | D16: Nashik | E16: Maharashtra | F16: West | G16: Audio | H16: Wireless Earbuds | I16: 4 | J16: 4500 | K16: 0 | L16: 18000 | M16: =CleanSalesTable[[#This Row],[Sales Amount]]-CleanSalesTable[[#This Row],[Unit Price]] -> 13500 | N16: UPI | O16: Kavya | P16: =IF(L16>=100000,"High",IF(L16>=30000,"Medium","Low")) -> Low | Q16: =IF(M16>0,"Profit","Loss") -> Profit | R16: =TEXT(B16,"mmm") -> Apr
... A324: ORD-1320 | B324: 45805 | C324: Neha Patil | D324: Rohini | E324: Delhi | F324: North | G324: Accessories | H324: Keyboard | I324: 2 | J324: 1500 | K324: 0.05 | L324: 2850 | M324: =CleanSalesTable[[#This Row],[Sales Amount]]-CleanSalesTable[[#This Row],[Unit Price]] -> 1350 | N324: Net Banking | O324: Aditya | P324: =IF(L324>=100000,"High",IF(L324>=30000,"Medium","Low")) -> Low | Q324: =IF(M324>0,"Profit","Loss") -> Profit | R324: =TEXT(B324,"mmm") -> May

Sheet Analysis
A1: SALES ANALYSIS AND FORMULAS
A4: KPI | B4: Formula Result | D4: Order ID Input | E4: XLOOKUP Sales | F4: INDEX-MATCH Product | G4: IF Sales Level | H4: Customer
A5: Total Sales | B5: =SUM(Clean_Data!L5:L324) -> 13739070 | D5: ORD-1001 | E5: =_xlfn.SINGLE(_xlfn.XLOOKUP(D5,Clean_Data!A5:A324,Clean_Data!L5:L324,"Not Found")) -> 3000 | F5: =INDEX(Clean_Data!H5:H324,MATCH(D5,Clean_Data!A5:A324,0)) -> Keyboard | G5: =IF(E5>=100000,"High",IF(E5>=30000,"Medium","Low")) -> Low | H5: =_xlfn.XLOOKUP(D5,Clean_Data!A5:A324,Clean_Data!C5:C324,"Not Found") -> Karan Joshi
A6: Total Profit | B6: =SUM(Clean_Data!M5:M324) -> 7749870
A7: Average Order Value | B7: =AVERAGE(Clean_Data!L5:L324) -> 42934.594
A8: Highest Sale | B8: =MAX(Clean_Data!L5:L324) -> 244000
A9: Lowest Sale | B9: =MIN(Clean_Data!L5:L324) -> 765
A10: Total Orders | B10: =COUNTA(Clean_Data!A5:A324) -> 320
A11: Orders with High Sales | B11: =COUNTIF(Clean_Data!P5:P324,"High") -> 42
A12: West Region Sales | B12: =SUMIF(Clean_Data!F5:F324,"West",Clean_Data!L5:L324) -> 4616720
A15: Formula | B15: Purpose | C15: Example Result
A16: SUM / SUMIF | B16: Total and conditional total
A17: COUNTIF / AVERAGE | B17: Count and average calculations
A18: XLOOKUP / INDEX-MATCH / IF | B18: Lookup and logical classification

Sheet Summary output
A1: SUMMARY OUTPUT
A3: Regression Statistics
A4: Multiple R | B4: 0.33577572
A5: R Square | B5: 0.11274533
A6: Adjusted R Square | B6: 0.10994642
A7: Standard Error | B7: 1.0430113
A8: Observations | B8: 319
A10: ANOVA
B11: df | C11: SS | D11: MS | E11: F | F11: Significance F
A12: Regression | B12: 1 | C12: 43.821531 | D12: 43.821531 | E12: 40.281863 | F12: 7.5953436e-10
A13: Residual | B13: 317 | C13: 344.85558 | D13: 1.0878725
A14: Total | B14: 318 | C14: 388.67712
B16: Coefficients | C16: Standard Error | D16: t Stat | E16: P-value | F16: Lower 95% | G16: Upper 95% | H16: Lower 95.0% | I16: Upper 95.0%
A17: Intercept | B17: 2.1348003 | C17: 0.075849439 | D17: 28.145235 | E17: 3.2380672e-88 | F17: 1.9855684 | G17: 2.2840322 | H17: 1.9855684 | I17: 2.2840322
A18: 3000 | B18: 7.1344069e-06 | C18: 1.1240952e-06 | D18: 6.3467994 | E18: 7.5953436e-10 | F18: 4.9227769e-06 | G18: 9.3460368e-06 | H18: 4.9227769e-06 | I18: 9.3460368e-06
A22: RESIDUAL OUTPUT | F22: PROBABILITY OUTPUT
A24: Observation | B24: Predicted 2 | C24: Residuals | D24: Standard Residuals | F24: Percentile | G24: 2
A25: 1 | B25: 2.6227937 | C25: -0.6227937 | D25: -0.59805227 | F25: 0.15673981 | G25: 1
A26: 2 | B26: 2.152779 | C26: -1.152779 | D26: -1.1069831 | F26: 0.47021944 | G26: 1
A27: 3 | B27: 2.1493545 | C27: -0.14935447 | D27: -0.14342113 | F27: 0.78369906 | G27: 1
A28: 4 | B28: 2.3081664 | C28: -0.30816636 | D28: -0.29592398 | F28: 1.0971787 | G28: 1
A29: 5 | B29: 2.9210119 | C29: -0.92101191 | D29: -0.8844233 | F29: 1.4106583 | G29: 1
A30: 6 | B30: 2.1652999 | C30: -1.1652999 | D30: -1.1190065 | F30: 1.7241379 | G30: 1
A31: 7 | B31: 3.0051979 | C31: -1.0051979 | D31: -0.96526488 | F31: 2.0376176 | G31: 1
A32: 8 | B32: 3.3761871 | C32: -0.37618707 | D32: -0.36124246 | F32: 2.3510972 | G32: 1
A33: 9 | B33: 2.1620894 | C33: -1.1620894 | D33: -1.1159236 | F33: 2.6645768 | G33: 1
A34: 10 | B34: 2.48724 | C34: -1.48724 | D34: -1.4281571 | F34: 2.9780564 | G34: 1
A35: 11 | B35: 2.2632196 | C35: 1.7367804 | D35: 1.6677841 | F35: 3.2915361 | G35: 1
A36: 12 | B36: 2.55359 | C36: 0.44641004 | D36: 0.42867572 | F36: 3.6050157 | G36: 1
... A343: 319 | B343: 2.1551333 | C343: -0.15513334 | D343: -0.14897043 | F343: 99.84326 | G343: 4

Sheet Pivot_Reports
A1: SUMMARY REPORTS (PIVOT-STYLE)
A4: Total Sales | C4: Total Profit | E4: Highest Sales | G4: Lowest Sales | I4: Total Order | K4: Avg order value
A5: =Analysis!B5 -> 13739070 | C5: =Analysis!B6 -> 7749870 | E5: =Analysis!B8 -> 244000 | G5: =Analysis!B9 -> 765 | I5: =Analysis!B10 -> 320 | K5: =Analysis!B7 -> 42934.594
A8: Row Labels | B8: Sum of Sales Amount | C8: Sum of Profit | F8: Category | G8: Total Sales | H8: Total Profit | J8: Month | K8: Monthly Sales
A9: North | B9: 4622700 | C9: 2614500 | F9: Laptop | G9: =SUMIF(Clean_Data!G$5:G$324,F9,Clean_Data!L$5:L$324) -> 7203550 | H9: =SUMIF(Clean_Data!G$5:G$324,F9,Clean_Data!M$5:M$324) -> 4103550 | J9: Jan | K9: =SUMIF(Clean_Data!R$5:R$324,J9,Clean_Data!L$5:L$324) -> 1198425
A10: South | B10: 4499650 | C10: 2421750 | F10: Mobile | G10: =SUMIF(Clean_Data!G$5:G$324,F10,Clean_Data!L$5:L$324) -> 3269350 | H10: =SUMIF(Clean_Data!G$5:G$324,F10,Clean_Data!M$5:M$324) -> 1697350 | J10: Feb | K10: =SUMIF(Clean_Data!R$5:R$324,J10,Clean_Data!L$5:L$324) -> 1082585
A11: West | B11: 4616720 | C11: 2713620 | F11: Accessories | G11: =SUMIF(Clean_Data!G$5:G$324,F11,Clean_Data!L$5:L$324) -> 189390 | H11: =SUMIF(Clean_Data!G$5:G$324,F11,Clean_Data!M$5:M$324) -> 104190 | J11: Mar | K11: =SUMIF(Clean_Data!R$5:R$324,J11,Clean_Data!L$5:L$324) -> 1174210
A12: Grand Total | B12: 13739070 | C12: 7749870 | F12: Audio | G12: =SUMIF(Clean_Data!G$5:G$324,F12,Clean_Data!L$5:L$324) -> 611905 | H12: =SUMIF(Clean_Data!G$5:G$324,F12,Clean_Data!M$5:M$324) -> 377405 | J12: Apr | K12: =SUMIF(Clean_Data!R$5:R$324,J12,Clean_Data!L$5:L$324) -> 1281480
F13: Monitor | G13: =SUMIF(Clean_Data!G$5:G$324,F13,Clean_Data!L$5:L$324) -> 2464875 | H13: =SUMIF(Clean_Data!G$5:G$324,F13,Clean_Data!M$5:M$324) -> 1467375 | J13: May | K13: =SUMIF(Clean_Data!R$5:R$324,J13,Clean_Data!L$5:L$324) -> 1545880
J14: Jun | K14: =SUMIF(Clean_Data!R$5:R$324,J14,Clean_Data!L$5:L$324) -> 1307730
J15: Jul | K15: =SUMIF(Clean_Data!R$5:R$324,J15,Clean_Data!L$5:L$324) -> 900495
J16: Aug | K16: =SUMIF(Clean_Data!R$5:R$324,J16,Clean_Data!L$5:L$324) -> 1055330
J17: Sep | K17: =SUMIF(Clean_Data!R$5:R$324,J17,Clean_Data!L$5:L$324) -> 1015040
J18: Oct | K18: =SUMIF(Clean_Data!R$5:R$324,J18,Clean_Data!L$5:L$324) -> 814770
J19: Nov | K19: =SUMIF(Clean_Data!R$5:R$324,J19,Clean_Data!L$5:L$324) -> 1338145
J20: Dec | K20: =SUMIF(Clean_Data!R$5:R$324,J20,Clean_Data!L$5:L$324) -> 1024980
A32: State | B32: Orders | C32: Sales | F32: Row Labels | G32: Sum of Sales Amount | I32: Region | J32: - all -
A33: Maharashtra | B33: =COUNTIF(Clean_Data!E$5:E$324,A33) -> 45 | C33: =SUMIF(Clean_Data!E$5:E$324,A33,Clean_Data!L$5:L$324) -> 1718335 | F33: Cash | G33: 2552815
A34: Gujarat | B34: =COUNTIF(Clean_Data!E$5:E$324,A34) -> 56 | C34: =SUMIF(Clean_Data!E$5:E$324,A34,Clean_Data!L$5:L$324) -> 2898385 | F34: Credit Card | G34: 2332890 | J34: Data
A35: Delhi | B35: =COUNTIF(Clean_Data!E$5:E$324,A35) -> 57 | C35: =SUMIF(Clean_Data!E$5:E$324,A35,Clean_Data!L$5:L$324) -> 2519510 | F35: Debit Card | G35: 3169205 | I35: Salesperson | J35: Sum of Profit | K35: Sum of Sales Amount
A36: Karnataka | B36: =COUNTIF(Clean_Data!E$5:E$324,A36) -> 48 | C36: =SUMIF(Clean_Data!E$5:E$324,A36,Clean_Data!L$5:L$324) -> 1871540 | F36: Net Banking | G36: 3698300 | I36: Aarav | J36: 1161910 | K36: 1845010
A37: Rajasthan | B37: =COUNTIF(Clean_Data!E$5:E$324,A37) -> 55 | C37: =SUMIF(Clean_Data!E$5:E$324,A37,Clean_Data!L$5:L$324) -> 2103190 | F37: UPI | G37: 1985860 | I37: Aditya | J37: 746450 | K37: 1539250
A38: Tamil Nadu | B38: =COUNTIF(Clean_Data!E$5:E$324,A38) -> 59 | C38: =SUMIF(Clean_Data!E$5:E$324,A38,Clean_Data!L$5:L$324) -> 2628110 | F38: Grand Total | G38: 13739070 | I38: Diya | J38: 1443910 | K38: 2724910
I39: Isha | J39: 1105455 | K39: 2071455
B40: Data | I40: Kavya | J40: 1358035 | K40: 2256035
A41: State | B41: Sum of Orders | C41: Sum of Sales | I41: Meera | J41: 648415 | K41: 1058315
A42: Delhi | B42: 57 | C42: 2519510 | I42: Rohan | J42: 551395 | K42: 1060195
A43: Gujarat | B43: 56 | C43: 2898385 | I43: Vivaan | J43: 734300 | K43: 1183900
A44: Karnataka | B44: 48 | C44: 1871540 | I44: Total Result | J44: 7749870 | K44: 13739070
A45: Maharashtra | B45: 45 | C45: 1718335
A46: Rajasthan | B46: 55 | C46: 2103190
A47: Tamil Nadu | B47: 59 | C47: 2628110
A48: Total Result | B48: 320 | C48: 13739070

Sheet Lists
A1: State | B1: Category | C1: Region
A2: Maharashtra | B2: Laptop | C2: All
A3: Gujarat | B3: Mobile | C3: North
A4: Delhi | B4: Accessories | C4: South
A5: Karnataka | B5: Audio | C5: West
A6: Rajasthan | B6: Monitor
A7: Tamil Nadu

Sheet Dashboard
A1: ELECTRONICS SALES DASHBOARD
A4: Filter | B4: Selection | D4: TOTAL SALES | G4: TOTAL PROFIT | J4: TOTAL ORDERS
A5: State | B5: All | D5: =SUMPRODUCT(--((($B$5="All")+(Clean_Data!$E$5:$E$324=$B$5))>0)*--((($B$6="All")+(Clean_Data!$G$5:$G$324=$B$6))>0)*--((($B$7="All")+(Clean_Data!$F$5:$F$324=$B$7))>0),Clean_Data!$L$5:$L$324) -> 13739070 | G5: =SUMPRODUCT(--((($B$5="All")+(Clean_Data!$E$5:$E$324=$B$5))>0)*--((($B$6="All")+(Clean_Data!$G$5:$G$324=$B$6))>0)*--((($B$7="All")+(Clean_Data!$F$5:$F$324=$B$7))>0),Clean_Data!$M$5:$M$324) -> 7749870 | J5: =SUMPRODUCT(--((($B$5="All")+(Clean_Data!$E$5:$E$324=$B$5))>0)*--((($B$6="All")+(Clean_Data!$G$5:$G$324=$B$6))>0)*--((($B$7="All")+(Clean_Data!$F$5:$F$324=$B$7))>0)) -> 320
A6: Category | B6: All
A7: Region | B7: All
D8: AVG ORDER VALUE
D9: =IFERROR(D5/J5,0) -> 42934.594
A13: Category | B13: Sales | D13: Payment Mode | E13: Orders | G13: Month | H13: Sales
A14: Laptop | B14: =SUMIF(Clean_Data!G$5:G$324,A14,Clean_Data!L$5:L$324) -> 7203550 | D14: UPI | E14: =COUNTIF(Clean_Data!N$5:N$324,D14) -> 52 | G14: Jan | H14: =SUMIF(Clean_Data!R$5:R$324,G14,Clean_Data!L$5:L$324) -> 1198425
A15: Mobile | B15: =SUMIF(Clean_Data!G$5:G$324,A15,Clean_Data!L$5:L$324) -> 3269350 | D15: Credit Card | E15: =COUNTIF(Clean_Data!N$5:N$324,D15) -> 49 | G15: Feb | H15: =SUMIF(Clean_Data!R$5:R$324,G15,Clean_Data!L$5:L$324) -> 1082585
A16: Accessories | B16: =SUMIF(Clean_Data!G$5:G$324,A16,Clean_Data!L$5:L$324) -> 189390 | D16: Debit Card | E16: =COUNTIF(Clean_Data!N$5:N$324,D16) -> 81 | G16: Mar | H16: =SUMIF(Clean_Data!R$5:R$324,G16,Clean_Data!L$5:L$324) -> 1174210
A17: Audio | B17: =SUMIF(Clean_Data!G$5:G$324,A17,Clean_Data!L$5:L$324) -> 611905 | D17: Cash | E17: =COUNTIF(Clean_Data!N$5:N$324,D17) -> 62 | G17: Apr | H17: =SUMIF(Clean_Data!R$5:R$324,G17,Clean_Data!L$5:L$324) -> 1281480
A18: Monitor | B18: =SUMIF(Clean_Data!G$5:G$324,A18,Clean_Data!L$5:L$324) -> 2464875 | D18: Net Banking | E18: =COUNTIF(Clean_Data!N$5:N$324,D18) -> 76 | G18: May | H18: =SUMIF(Clean_Data!R$5:R$324,G18,Clean_Data!L$5:L$324) -> 1545880
G19: Jun | H19: =SUMIF(Clean_Data!R$5:R$324,G19,Clean_Data!L$5:L$324) -> 1307730
G20: Jul | H20: =SUMIF(Clean_Data!R$5:R$324,G20,Clean_Data!L$5:L$324) -> 900495
G21: Aug | H21: =SUMIF(Clean_Data!R$5:R$324,G21,Clean_Data!L$5:L$324) -> 1055330
G22: Sep | H22: =SUMIF(Clean_Data!R$5:R$324,G22,Clean_Data!L$5:L$324) -> 1015040
G23: Oct | H23: =SUMIF(Clean_Data!R$5:R$324,G23,Clean_Data!L$5:L$324) -> 814770
G24: Nov | H24: =SUMIF(Clean_Data!R$5:R$324,G24,Clean_Data!L$5:L$324) -> 1338145
G25: Dec | H25: =SUMIF(Clean_Data!R$5:R$324,G25,Clean_Data!L$5:L$324) -> 1024980
F64: Region | G64: - all -
A66: Row Labels | B66: Sum of Sales Amount | C66: Sum of Profit | G66: Data
A67: North | B67: 4622700 | C67: 2614500 | F67: Salesperson | G67: Sum of Profit | H67: Sum of Sales Amount
A68: South | B68: 4499650 | C68: 2421750 | F68: Aarav | G68: 1161910 | H68: 1845010
A69: West | B69: 4616720 | C69: 2713620 | F69: Aditya | G69: 746450 | H69: 1539250
A70: Grand Total | B70: 13739070 | C70: 7749870 | F70: Diya | G70: 1443910 | H70: 2724910
F71: Isha | G71: 1105455 | H71: 2071455
F72: Kavya | G72: 1358035 | H72: 2256035
F73: Meera | G73: 648415 | H73: 1058315
F74: Rohan | G74: 551395 | H74: 1060195
F75: Vivaan | G75: 734300 | H75: 1183900
F76: Total Result | G76: 7749870 | H76: 13739070
A90: State | B90: Orders | C90: Sales
A91: Maharashtra | B91: =COUNTIF(Clean_Data!E$5:E$324,A91) -> 45 | C91: =SUMIF(Clean_Data!E$5:E$324,A91,Clean_Data!L$5:L$324) -> 1718335
A92: Gujarat | B92: =COUNTIF(Clean_Data!E$5:E$324,A92) -> 56 | C92: =SUMIF(Clean_Data!E$5:E$324,A92,Clean_Data!L$5:L$324) -> 2898385
A93: Delhi | B93: =COUNTIF(Clean_Data!E$5:E$324,A93) -> 57 | C93: =SUMIF(Clean_Data!E$5:E$324,A93,Clean_Data!L$5:L$324) -> 2519510
A94: Karnataka | B94: =COUNTIF(Clean_Data!E$5:E$324,A94) -> 48 | C94: =SUMIF(Clean_Data!E$5:E$324,A94,Clean_Data!L$5:L$324) -> 1871540
A95: Rajasthan | B95: =COUNTIF(Clean_Data!E$5:E$324,A95) -> 55 | C95: =SUMIF(Clean_Data!E$5:E$324,A95,Clean_Data!L$5:L$324) -> 2103190
A96: Tamil Nadu | B96: =COUNTIF(Clean_Data!E$5:E$324,A96) -> 59 | C96: =SUMIF(Clean_Data!E$5:E$324,A96,Clean_Data!L$5:L$324) -> 2628110
B98: Data
...

Sheet Documentation
A1: PROJECT DOCUMENTATION
A4: Author | B4: Tej Patel
A5: Project Name | B5: Electronics Sales Dashboard
A6: Dataset Type | B6: Sales – Electronics Products
A7: Excel Version | B7: Microsoft Excel 365 / Updated Version
A8: Total Records | B8: 320
A9: Main Sheets | B9: Raw_Data, Clean_Data, Analysis, Pivot_Reports, Dashboard
A10: Formulas Used | B10: SUM, AVERAGE, MAX, MIN, COUNTIF, SUMIF, IF, XLOOKUP, INDEX-MATCH, SUMPRODUCT
A11: Features Used | B11: Tables, formatting, data validation, conditional formatting, charts and dashboard
A12: Dashboard Filters | B12: State, Category and Region dropdowns
A13: Note | B13: Project is intentionally simple and suitable for a beginner practical exam.
A16: Total Sales | C16: Total Profit | E16: Highest Sales | G16: Lowest Sales | I16: Total Order | K16: Avg order value
A17: =Analysis!B5 -> 13739070 | C17: =Analysis!B6 -> 7749870 | E17: =Analysis!B8 -> 244000 | G17: =Analysis!B9 -> 765 | I17: =Analysis!B10 -> 320 | K17: =Analysis!B7 -> 42934.594
A20: Row Labels | B20: Sum of Sales Amount | C20: Sum of Profit | F20: Category | G20: Total Sales | H20: Total Profit | J20: Month | K20: Monthly Sales
A21: North | B21: 4622700 | C21: 2614500 | F21: Laptop | G21: =SUMIF(Clean_Data!G$5:G$324,F21,Clean_Data!L$5:L$324) -> 7203550 | H21: =SUMIF(Clean_Data!G$5:G$324,F21,Clean_Data!M$5:M$324) -> 4103550 | J21: Jan | K21: =SUMIF(Clean_Data!R$5:R$324,J21,Clean_Data!L$5:L$324) -> 1198425
A22: South | B22: 4499650 | C22: 2421750 | F22: Mobile | G22: =SUMIF(Clean_Data!G$5:G$324,F22,Clean_Data!L$5:L$324) -> 3269350 | H22: =SUMIF(Clean_Data!G$5:G$324,F22,Clean_Data!M$5:M$324) -> 1697350 | J22: Feb | K22: =SUMIF(Clean_Data!R$5:R$324,J22,Clean_Data!L$5:L$324) -> 1082585
A23: West | B23: 4616720 | C23: 2713620 | F23: Accessories | G23: =SUMIF(Clean_Data!G$5:G$324,F23,Clean_Data!L$5:L$324) -> 189390 | H23: =SUMIF(Clean_Data!G$5:G$324,F23,Clean_Data!M$5:M$324) -> 104190 | J23: Mar | K23: =SUMIF(Clean_Data!R$5:R$324,J23,Clean_Data!L$5:L$324) -> 1174210
A24: Grand Total | B24: 13739070 | C24: 7749870 | F24: Audio | G24: =SUMIF(Clean_Data!G$5:G$324,F24,Clean_Data!L$5:L$324) -> 611905 | H24: =SUMIF(Clean_Data!G$5:G$324,F24,Clean_Data!M$5:M$324) -> 377405 | J24: Apr | K24: =SUMIF(Clean_Data!R$5:R$324,J24,Clean_Data!L$5:L$324) -> 1281480
F25: Monitor | G25: =SUMIF(Clean_Data!G$5:G$324,F25,Clean_Data!L$5:L$324) -> 2464875 | H25: =SUMIF(Clean_Data!G$5:G$324,F25,Clean_Data!M$5:M$324) -> 1467375 | J25: May | K25: =SUMIF(Clean_Data!R$5:R$324,J25,Clean_Data!L$5:L$324) -> 1545880
J26: Jun | K26: =SUMIF(Clean_Data!R$5:R$324,J26,Clean_Data!L$5:L$324) -> 1307730
J27: Jul | K27: =SUMIF(Clean_Data!R$5:R$324,J27,Clean_Data!L$5:L$324) -> 900495
J28: Aug | K28: =SUMIF(Clean_Data!R$5:R$324,J28,Clean_Data!L$5:L$324) -> 1055330
J29: Sep | K29: =SUMIF(Clean_Data!R$5:R$324,J29,Clean_Data!L$5:L$324) -> 1015040
J30: Oct | K30: =SUMIF(Clean_Data!R$5:R$324,J30,Clean_Data!L$5:L$324) -> 814770
J31: Nov | K31: =SUMIF(Clean_Data!R$5:R$324,J31,Clean_Data!L$5:L$324) -> 1338145
J32: Dec | K32: =SUMIF(Clean_Data!R$5:R$324,J32,Clean_Data!L$5:L$324) -> 1024980
A44: State | B44: Orders | C44: Sales | F44: Row Labels | G44: Sum of Sales Amount | I44: Region | J44: - all -
A45: Maharashtra | B45: =COUNTIF(Clean_Data!E$5:E$324,A45) -> 45 | C45: =SUMIF(Clean_Data!E$5:E$324,A45,Clean_Data!L$5:L$324) -> 1718335 | F45: Cash | G45: 2552815
A46: Gujarat | B46: =COUNTIF(Clean_Data!E$5:E$324,A46) -> 56 | C46: =SUMIF(Clean_Data!E$5:E$324,A46,Clean_Data!L$5:L$324) -> 2898385 | F46: Credit Card | G46: 2332890 | J46: Data
A47: Delhi | B47: =COUNTIF(Clean_Data!E$5:E$324,A47) -> 57 | C47: =SUMIF(Clean_Data!E$5:E$324,A47,Clean_Data!L$5:L$324) -> 2519510 | F47: Debit Card | G47: 3169205 | I47: Salesperson | J47: Sum of Profit | K47: Sum of Sales Amount
A48: Karnataka | B48: =COUNTIF(Clean_Data!E$5:E$324,A48) -> 48 | C48: =SUMIF(Clean_Data!E$5:E$324,A48,Clean_Data!L$5:L$324) -> 1871540 | F48: Net Banking | G48: 3698300 | I48: Aarav | J48: 1161910 | K48: 1845010
A49: Rajasthan | B49: =COUNTIF(Clean_Data!E$5:E$324,A49) -> 55 | C49: =SUMIF(Clean_Data!E$5:E$324,A49,Clean_Data!L$5:L$324) -> 2103190 | F49: UPI | G49: 1985860 | I49: Aditya | J49: 746450 | K49: 1539250
A50: Tamil Nadu | B50: =COUNTIF(Clean_Data!E$5:E$324,A50) -> 59 | C50: =SUMIF(Clean_Data!E$5:E$324,A50,Clean_Data!L$5:L$324) -> 2628110 | F50: Grand Total | G50: 13739070 | I50: Diya | J50: 1443910 | K50: 2724910
I51: Isha | J51: 1105455 | K51: 2071455
B52: Data | I52: Kavya | J52: 1358035 | K52: 2256035
A53: State | B53: Sum of Orders | C53: Sum of Sales | I53: Meera | J53: 648415 | K53: 1058315
A54: Delhi | B54: 57 | C54: 2519510 | I54: Rohan | J54: 551395 | K54: 1060195
A55: Gujarat | B55: 56 | C55: 2898385 | I55: Vivaan | J55: 734300 | K55: 1183900
A56: Karnataka | B56: 48 | C56: 1871540 | I56: Total Result | J56: 7749870 | K56: 13739070
A57: Maharashtra | B57: 45 | C57: 1718335
...
